<?xml version="1.0" ?>
<!-- =================================================================================== -->
<!-- |    This document was autogenerated by xacro from arm_and_hand_motor_ellipsoid.urdf.xacro | -->
<!-- |    EDITING THIS FILE BY HAND IS NOT RECOMMENDED                                 | -->
<!-- =================================================================================== -->
<robot name="arm_and_hand">
    <material name="Blue">
        <color rgba="0.0 0.0 0.8 1.0"/>
    </material>
    <material name="Green">
        <color rgba="0.0 0.8 0.0 1.0"/>
    </material>
    <material name="Grey">
        <color rgba="0.2 0.2 0.2 1.0"/>
    </material>
    <material name="LightGrey">
        <color rgba="0.6 0.6 0.6 1.0"/>
    </material>
    <material name="Red">
        <color rgba="0.8 0.0 0.0 1.0"/>
    </material>
    <material name="White">
        <color rgba="1.0 1.0 1.0 1.0"/>
    </material>
    <link name="world"/>
    <joint name="arm_to_world_fixed" type="fixed">
        <parent link="world"/>
        <child link="shadowarm_lowerarm"/>
        <origin rpy="0 0 0" xyz="0 0 0"/>
    </joint>
    
    <link name="shadowarm_lowerarm">
        <inertial>
            <origin rpy="0 0 0" xyz="0.08 0 0.0625"/>
            <mass value="1.7"/>
            <inertia ixx="1.0" ixy="0.0" ixz="0.0" iyy="0.0" iyz="0.0" izz="0.0"/>
        </inertial>
        <visual>
            <origin rpy="0 0 0" xyz="0.03 0 0.036"/>
            <geometry name="shadowarm_lowerarm_visual">
                <mesh filename="sr_description/arm/model/elbow_flex.dae" scale="0.001 0.001 0.001"/>
            </geometry>
            <material name="Grey"/>
        </visual>
        <collision>
            <origin rpy="0 0 0" xyz="0.08 0 0.0625"/>
            <geometry name="shadowarm_lowerarm_collision">
                <box size="0.03 0.03 0.10"/>
            </geometry>
        </collision>
    </link>
    <link name="shadowarm_handsupport">
        <inertial>
            <origin rpy="0 0 0" xyz="0 0 0"/>
            <mass value="0.75"/>
            <inertia ixx="1.0" ixy="0.0" ixz="0.0" iyy="0.0" iyz="0.0" izz="0.0"/>
        </inertial>
        <visual>
            <origin rpy="0 0 0" xyz="0 0 -0.04"/>
            <geometry name="shadowarm_handsupport_visual">
                <mesh filename="sr_description/arm/model/elbow_rotate_motor.dae" scale="0.001 0.001 0.001"/>
            </geometry>
            <material name="LightGrey"/>
        </visual>
        <collision>
            <origin rpy="0 0 0" xyz="0 0 -0.005"/>
            <geometry name="shadowarm_handsupport_collision">
                <cylinder length="0.001" radius="0.06"/>
            </geometry>
        </collision>
    </link>
    <joint name="ElbowJRotate" type="revolute">
        <parent link="shadowarm_lowerarm"/>
        <child link="shadowarm_handsupport"/>
        <origin rpy="0.0 0 0" xyz="0.08 0 0.125"/>
        <axis xyz="0 0 -1"/>
        <limit effort="10" lower="-1.57079632679" upper="1.57079632679" velocity="1.0"/>
        <dynamics damping="10.5"/>
    </joint>
    <transmission name="forearm_rotation_transmission" type="sr_mechanism_model/SimpleTransmission">
        <actuator name="forearm_rotation"/>
        <joint name="ElbowJRotate"/>
        <mechanicalReduction>1</mechanicalReduction>
        <motorTorqueConstant>1</motorTorqueConstant>
        <pulsesPerRevolution>90000</pulsesPerRevolution>
    </transmission>
    <joint name="arm_link" type="fixed">
        <parent link="shadowarm_handsupport"/>
        <child link="forearm"/>
        <origin rpy="0 0 2.35619449" xyz="0 0 0"/>
    </joint>
    <link name="forearm">
        <inertial>
            <origin rpy="0 0 0" xyz="0 0 0.09"/>
            <mass value="3.0"/>
            <inertia ixx="1.0" ixy="0.0" ixz="0.0" iyy="1.0" iyz="0.0" izz="1.0"/>
        </inertial>
        <visual>
            <origin rpy="0 0 0" xyz="0 0 0"/>
            <geometry name="shadow_forearm_geom">
                <mesh filename="sr_description/hand/model/forearm.dae" scale="0.001 0.001 0.001"/>
            </geometry>
            <material name="Grey"/>
        </visual>
        <collision>
            <origin rpy="0 0 0" xyz="0 0 0.09"/>
            <geometry name="shadow_forearm_collision">
                <cylinder length="0.180" radius="0.06"/>
            </geometry>
        </collision>
    </link>
    <link name="wrist">
        <inertial>
            <origin rpy="0 0 0" xyz="0.0 0.0 0.01"/>
            <!--<insert_block name="origin" />-->
            <mass value="0.1"/>
            <inertia ixx="0.120" ixy="0.0" ixz="0.0" iyy="0.148" iyz="0.0" izz="0.0438"/>
        </inertial>
        <visual>
            <origin rpy="0 0 0" xyz="0 0 0"/>
            <geometry name="wrist_visual">
                <mesh filename="sr_description/hand/model/wrist.dae" scale="0.001 0.001 0.001"/>
            </geometry>
            <material name="LightGrey"/>
        </visual>
        <collision>
            <origin rpy="0 0 0" xyz="0 0 0"/>
            <geometry name="wrist_collision_geom">
                <mesh filename="sr_description/hand/model/wrist.dae" scale="0.001 0.001 0.001"/>
            </geometry>
        </collision>
    </link>
    <joint name="WRJ2" type="revolute">
        <parent link="forearm"/>
        <child link="wrist"/>
        <!--<origin xyz="0 -0.010 0.213" rpy="0 0 0" />-->
        <origin rpy="0 0 0" xyz="0 -0.010 0.213"/>
        <axis xyz="0 1 0"/>
        <limit effort="5" lower="-0.52359877559829882" upper="0.17453292519943295" velocity="1.0"/>
        <dynamics damping="100.5"/>
    </joint>
    <transmission name="wrist_transmission" type="sr_mechanism_model/SimpleTransmission">
        <actuator name="WRJ2"/>
        <joint name="WRJ2"/>
        <mechanicalReduction>1</mechanicalReduction>
        <motorTorqueConstant>1</motorTorqueConstant>
        <pulsesPerRevolution>90000</pulsesPerRevolution>
    </transmission>
    <link name="palm">
        <inertial>
            <origin rpy="0 0 0" xyz="0.0 0.0 0.04"/>
            <mass value="0.8"/>
            <inertia ixx="0.00045" ixy="0.0" ixz="0.0" iyy="0.00059" iyz="0.0" izz="0.00019"/>
        </inertial>
        <visual>
            <origin rpy="0 0 0" xyz="0 0 0"/>
            <geometry name="palm_visual">
                <mesh filename="sr_description/hand/model/palm.dae" scale="0.001 0.001 0.001"/>
            </geometry>
            <material name="Grey"/>
        </visual>
        <collision>
            <origin rpy="0 0 0" xyz="0 0 0"/>
            <geometry name="palm_collision_geom">
                <mesh filename="sr_description/hand/model/palm.dae" scale="0.001 0.001 0.001"/>
            </geometry>
        </collision>
    </link>
    <joint name="WRJ1" type="revolute">
        <parent link="wrist"/>
        <child link="palm"/>
        <origin rpy="0 0 0" xyz="0 0 0.034"/>
        <axis xyz="1 0 0"/>
        <limit effort="5" lower="-0.78539816339744828" upper="0.6108652381980153" velocity="1.0"/>
        <dynamics damping="100.5"/>
    </joint>
    <transmission name="palm_transmission" type="sr_mechanism_model/SimpleTransmission">
        <actuator name="WRJ1"/>
        <joint name="WRJ1"/>
        <mechanicalReduction>1</mechanicalReduction>
        <motorTorqueConstant>1</motorTorqueConstant>
        <pulsesPerRevolution>90000</pulsesPerRevolution>
    </transmission>
    <link name="ffknuckle">
        <inertial>
            <origin rpy="0 0 0" xyz="0.0 0.0 0.0"/>
            <!--<insert_block name="origin" /> -->
            <mass value="0.008"/>
            <inertia ixx="0.1" ixy="0.0" ixz="0.0" iyy="0.1" iyz="0.0" izz="0.1"/>
        </inertial>
        <visual>
            <origin rpy="0 0 0" xyz="0 0 0.0005"/>
            <geometry name="knuckle_visual">
                <mesh filename="sr_description/hand/model/knuckle.dae" scale="0.001 0.001 0.001"/>
            </geometry>
            <material name="LightGrey"/>
        </visual>
        <collision>
            <origin rpy="0 0 0" xyz="0 0 0.0005"/>
            <geometry name="knuckle_collision_geom">
                <mesh filename="sr_description/hand/model/knuckle.dae" scale="0.001 0.001 0.001"/>
            </geometry>
        </collision>
    </link>
    <joint name="FFJ4" type="revolute">
        <parent link="palm"/>
        <child link="ffknuckle"/>
        <!--<origin xyz="0.033 0 0.095" rpy="0 0 0" />-->
        <origin rpy="0 0 0" xyz="0.033 0 0.095"/>
        <axis xyz="0 -1 0"/>
        <limit effort="10" lower="-0.43633231299858238" upper="0.43633231299858238" velocity="1.0"/>
        <dynamics damping="50.5"/>
    </joint>
    <transmission name="ffknuckle_transmission" type="sr_mechanism_model/SimpleTransmission">
        <actuator name="FFJ4"/>
        <joint name="FFJ4"/>
        <mechanicalReduction>1</mechanicalReduction>
        <motorTorqueConstant>1</motorTorqueConstant>
        <pulsesPerRevolution>90000</pulsesPerRevolution>
    </transmission>
    <link name="ffproximal">
        <inertial>
            <mass value="0.2"/>
            <origin xyz="0 0 0.025"/>
            <inertia ixx="0.00003" ixy="0.0" ixz="0.0" iyy="0.00003" iyz="0.0" izz="0.0000075"/>
        </inertial>
        <visual>
            <origin rpy="0 0 0" xyz="0 0 0"/>
            <geometry name="proximal_visual">
                <mesh filename="sr_description/hand/model/F3.dae" scale="0.001 0.001 0.001"/>
            </geometry>
            <material name="Grey"/>
        </visual>
        <collision>
            <origin rpy="0 0 0 " xyz="0 0 0"/>
            <geometry name="proximal_collision_geom">
                <mesh filename="sr_description/hand/model/F3.dae" scale="0.001 0.001 0.001"/>
            </geometry>
        </collision>
    </link>
    <joint name="FFJ3" type="revolute">
        <parent link="ffknuckle"/>
        <child link="ffproximal"/>
        <origin rpy="0 0 0" xyz="0 0 0"/>
        <axis xyz="1 0 0"/>
        <limit effort="10" lower="0" upper="1.57079632679" velocity="1.0"/>
        <dynamics damping="50.5"/>
    </joint>
    <transmission name="ffproximal_transmission" type="sr_mechanism_model/SimpleTransmission">
        <actuator name="FFJ3"/>
        <joint name="FFJ3"/>
        <mechanicalReduction>1</mechanicalReduction>
        <motorTorqueConstant>1</motorTorqueConstant>
        <pulsesPerRevolution>90000</pulsesPerRevolution>
    </transmission>
    <link name="ffmiddle">
        <inertial>
            <origin rpy="0 0 0" xyz="0 0 0.0125"/>
            <mass value="0.1"/>
            <inertia ixx="0.0000067" ixy="0.0" ixz="0.0" iyy="0.0000067" iyz="0.0" izz="0.0000038"/>
        </inertial>
        <visual>
            <origin rpy="0 0 0" xyz="0 0 0"/>
            <geometry name="middle_visual">
                <mesh filename="sr_description/hand/model/F2.dae" scale="0.001 0.001 0.001"/>
            </geometry>
            <material name="Grey"/>
        </visual>
        <collision>
            <origin rpy="0 0 0" xyz="0 0 0"/>
            <geometry name="middle_collision_geom">
                <mesh filename="sr_description/hand/model/F2.dae" scale="0.001 0.001 0.001"/>
            </geometry>
        </collision>
    </link>
    <joint name="FFJ2" type="revolute">
        <parent link="ffproximal"/>
        <child link="ffmiddle"/>
        <origin rpy="0 0 0" xyz="0 0 0.045"/>
        <axis xyz="1 0 0"/>
        <limit effort="10" lower="0" upper="1.57079632679" velocity="1.0"/>
        <dynamics damping="50.5"/>
    </joint>
    <transmission name="ffmiddle_transmission" type="sr_mechanism_model/J0Transmission">
        <actuator name="FFJ0"/>
        <joint1 name="FFJ1"/>
        <joint2 name="FFJ2"/>
        <mechanicalReduction>1</mechanicalReduction>
        <motorTorqueConstant>1</motorTorqueConstant>
        <pulsesPerRevolution>90000</pulsesPerRevolution>
    </transmission>
    <link name="ffdistal">
        <inertial>
            <mass value="0.1"/>
            <origin xyz="0 0 0.018"/>
            <inertia ixx="0.0000067" ixy="0.0" ixz="0.0" iyy="0.0000067" iyz="0.0" izz="0.0000038"/>
        </inertial>
        <visual>
            <origin rpy="0 0 0" xyz="0 0 0"/>
            <geometry name="distal_visual">
                <mesh filename="sr_description/hand/model/distal_ellipsoid.dae" scale="0.001 0.001 0.001"/>
            </geometry>
            <material name="Grey"/>
        </visual>
        <collision>
            <origin rpy="0 0 0" xyz="0 0 0"/>
            <geometry name="distal_collision_geom">
                <mesh filename="sr_description/hand/model/distal_ellipsoid.dae" scale="0.001 0.001 0.001"/>
            </geometry>
        </collision>
    </link>
    <joint name="FFJ1" type="revolute">
        <parent link="ffmiddle"/>
        <child link="ffdistal"/>
        <origin rpy="0 0 0" xyz="0 0 0.025"/>
        <axis xyz="1 0 0"/>
        <limit effort="10" lower="0" upper="1.57079632679" velocity="1.0"/>
        <dynamics damping="50.5"/>
    </joint>
    <link name="fftip">
        <inertial>
            <mass value="0.001"/>
            <inertia ixx="0.0" ixy="0.0" ixz="0.0" iyy="0.0" iyz="0.0" izz="0.0"/>
        </inertial>
    </link>
    <joint name="FFtip" type="fixed">
        <parent link="ffdistal"/>
        <child link="fftip"/>
        <origin rpy="0 0 0" xyz="0 0 0.026"/>
    </joint>
    <link name="mfknuckle">
        <inertial>
            <origin rpy="0 0 0" xyz="0 0 0"/>
            <!--<insert_block name="origin" /> -->
            <mass value="0.008"/>
            <inertia ixx="0.1" ixy="0.0" ixz="0.0" iyy="0.1" iyz="0.0" izz="0.1"/>
        </inertial>
        <visual>
            <origin rpy="0 0 0" xyz="0 0 0.0005"/>
            <geometry name="knuckle_visual">
                <mesh filename="sr_description/hand/model/knuckle.dae" scale="0.001 0.001 0.001"/>
            </geometry>
            <material name="LightGrey"/>
        </visual>
        <collision>
            <origin rpy="0 0 0" xyz="0 0 0.0005"/>
            <geometry name="knuckle_collision_geom">
                <mesh filename="sr_description/hand/model/knuckle.dae" scale="0.001 0.001 0.001"/>
            </geometry>
        </collision>
    </link>
    <joint name="MFJ4" type="revolute">
        <parent link="palm"/>
        <child link="mfknuckle"/>
        <!--<origin xyz="0.033 0 0.095" rpy="0 0 0" />-->
        <origin rpy="0 0 0" xyz="0.011 0 0.099"/>
        <axis xyz="0 -1 0"/>
        <limit effort="10" lower="-0.43633231299858238" upper="0.43633231299858238" velocity="1.0"/>
        <dynamics damping="50.5"/>
    </joint>
    <transmission name="mfknuckle_transmission" type="sr_mechanism_model/SimpleTransmission">
        <actuator name="MFJ4"/>
        <joint name="MFJ4"/>
        <mechanicalReduction>1</mechanicalReduction>
        <motorTorqueConstant>1</motorTorqueConstant>
        <pulsesPerRevolution>90000</pulsesPerRevolution>
    </transmission>
    <link name="mfproximal">
        <inertial>
            <mass value="0.2"/>
            <origin xyz="0 0 0.025"/>
            <inertia ixx="0.00003" ixy="0.0" ixz="0.0" iyy="0.00003" iyz="0.0" izz="0.0000075"/>
        </inertial>
        <visual>
            <origin rpy="0 0 0" xyz="0 0 0"/>
            <geometry name="proximal_visual">
                <mesh filename="sr_description/hand/model/F3.dae" scale="0.001 0.001 0.001"/>
            </geometry>
            <material name="Grey"/>
        </visual>
        <collision>
            <origin rpy="0 0 0 " xyz="0 0 0"/>
            <geometry name="proximal_collision_geom">
                <mesh filename="sr_description/hand/model/F3.dae" scale="0.001 0.001 0.001"/>
            </geometry>
        </collision>
    </link>
    <joint name="MFJ3" type="revolute">
        <parent link="mfknuckle"/>
        <child link="mfproximal"/>
        <origin rpy="0 0 0" xyz="0 0 0"/>
        <axis xyz="1 0 0"/>
        <limit effort="10" lower="0" upper="1.57079632679" velocity="1.0"/>
        <dynamics damping="50.5"/>
    </joint>
    <transmission name="mfproximal_transmission" type="sr_mechanism_model/SimpleTransmission">
        <actuator name="MFJ3"/>
        <joint name="MFJ3"/>
        <mechanicalReduction>1</mechanicalReduction>
        <motorTorqueConstant>1</motorTorqueConstant>
        <pulsesPerRevolution>90000</pulsesPerRevolution>
    </transmission>
    <link name="mfmiddle">
        <inertial>
            <origin rpy="0 0 0" xyz="0 0 0.0125"/>
            <mass value="0.1"/>
            <inertia ixx="0.0000067" ixy="0.0" ixz="0.0" iyy="0.0000067" iyz="0.0" izz="0.0000038"/>
        </inertial>
        <visual>
            <origin rpy="0 0 0" xyz="0 0 0"/>
            <geometry name="middle_visual">
                <mesh filename="sr_description/hand/model/F2.dae" scale="0.001 0.001 0.001"/>
            </geometry>
            <material name="Grey"/>
        </visual>
        <collision>
            <origin rpy="0 0 0" xyz="0 0 0"/>
            <geometry name="middle_collision_geom">
                <mesh filename="sr_description/hand/model/F2.dae" scale="0.001 0.001 0.001"/>
            </geometry>
        </collision>
    </link>
    <joint name="MFJ2" type="revolute">
        <parent link="mfproximal"/>
        <child link="mfmiddle"/>
        <origin rpy="0 0 0" xyz="0 0 0.045"/>
        <axis xyz="1 0 0"/>
        <limit effort="10" lower="0" upper="1.57079632679" velocity="1.0"/>
        <dynamics damping="50.5"/>
    </joint>
    <transmission name="mfmiddle_transmission" type="sr_mechanism_model/J0Transmission">
        <actuator name="MFJ0"/>
        <joint1 name="MFJ1"/>
        <joint2 name="MFJ2"/>
        <mechanicalReduction>1</mechanicalReduction>
        <motorTorqueConstant>1</motorTorqueConstant>
        <pulsesPerRevolution>90000</pulsesPerRevolution>
    </transmission>
    <link name="mfdistal">
        <inertial>
            <mass value="0.1"/>
            <origin xyz="0 0 0.018"/>
            <inertia ixx="0.0000067" ixy="0.0" ixz="0.0" iyy="0.0000067" iyz="0.0" izz="0.0000038"/>
        </inertial>
        <visual>
            <origin rpy="0 0 0" xyz="0 0 0"/>
            <geometry name="distal_visual">
                <mesh filename="sr_description/hand/model/distal_ellipsoid.dae" scale="0.001 0.001 0.001"/>
            </geometry>
            <material name="Grey"/>
        </visual>
        <collision>
            <origin rpy="0 0 0" xyz="0 0 0"/>
            <geometry name="distal_collision_geom">
                <mesh filename="sr_description/hand/model/distal_ellipsoid.dae" scale="0.001 0.001 0.001"/>
            </geometry>
        </collision>
    </link>
    <joint name="MFJ1" type="revolute">
        <parent link="mfmiddle"/>
        <child link="mfdistal"/>
        <origin rpy="0 0 0" xyz="0 0 0.025"/>
        <axis xyz="1 0 0"/>
        <limit effort="10" lower="0" upper="1.57079632679" velocity="1.0"/>
        <dynamics damping="50.5"/>
    </joint>
    <link name="mftip">
        <inertial>
            <mass value="0.001"/>
            <inertia ixx="0.0" ixy="0.0" ixz="0.0" iyy="0.0" iyz="0.0" izz="0.0"/>
        </inertial>
    </link>
    <joint name="MFtip" type="fixed">
        <parent link="mfdistal"/>
        <child link="mftip"/>
        <origin rpy="0 0 0" xyz="0 0 0.026"/>
    </joint>
    <link name="rfknuckle">
        <inertial>
            <origin rpy="0 0 0" xyz="0 0 0"/>
            <!--<insert_block name="origin" /> -->
            <mass value="0.008"/>
            <inertia ixx="0.1" ixy="0.0" ixz="0.0" iyy="0.1" iyz="0.0" izz="0.1"/>
        </inertial>
        <visual>
            <origin rpy="0 0 0" xyz="0 0 0.0005"/>
            <geometry name="knuckle_visual">
                <mesh filename="sr_description/hand/model/knuckle.dae" scale="0.001 0.001 0.001"/>
            </geometry>
            <material name="LightGrey"/>
        </visual>
        <collision>
            <origin rpy="0 0 0" xyz="0 0 0.0005"/>
            <geometry name="knuckle_collision_geom">
                <mesh filename="sr_description/hand/model/knuckle.dae" scale="0.001 0.001 0.001"/>
            </geometry>
        </collision>
    </link>
    <joint name="RFJ4" type="revolute">
        <parent link="palm"/>
        <child link="rfknuckle"/>
        <!--<origin xyz="0.033 0 0.095" rpy="0 0 0" />-->
        <origin rpy="0 0 0" xyz="-0.011 0 0.095"/>
        <axis xyz="0 1 0"/>
        <limit effort="10" lower="-0.43633231299858238" upper="0.43633231299858238" velocity="1.0"/>
        <dynamics damping="50.5"/>
    </joint>
    <transmission name="rfknuckle_transmission" type="sr_mechanism_model/SimpleTransmission">
        <actuator name="RFJ4"/>
        <joint name="RFJ4"/>
        <mechanicalReduction>1</mechanicalReduction>
        <motorTorqueConstant>1</motorTorqueConstant>
        <pulsesPerRevolution>90000</pulsesPerRevolution>
    </transmission>
    <link name="rfproximal">
        <inertial>
            <mass value="0.2"/>
            <origin xyz="0 0 0.025"/>
            <inertia ixx="0.00003" ixy="0.0" ixz="0.0" iyy="0.00003" iyz="0.0" izz="0.0000075"/>
        </inertial>
        <visual>
            <origin rpy="0 0 0" xyz="0 0 0"/>
            <geometry name="proximal_visual">
                <mesh filename="sr_description/hand/model/F3.dae" scale="0.001 0.001 0.001"/>
            </geometry>
            <material name="Grey"/>
        </visual>
        <collision>
            <origin rpy="0 0 0 " xyz="0 0 0"/>
            <geometry name="proximal_collision_geom">
                <mesh filename="sr_description/hand/model/F3.dae" scale="0.001 0.001 0.001"/>
            </geometry>
        </collision>
    </link>
    <joint name="RFJ3" type="revolute">
        <parent link="rfknuckle"/>
        <child link="rfproximal"/>
        <origin rpy="0 0 0" xyz="0 0 0"/>
        <axis xyz="1 0 0"/>
        <limit effort="10" lower="0" upper="1.57079632679" velocity="1.0"/>
        <dynamics damping="50.5"/>
    </joint>
    <transmission name="rfproximal_transmission" type="sr_mechanism_model/SimpleTransmission">
        <actuator name="RFJ3"/>
        <joint name="RFJ3"/>
        <mechanicalReduction>1</mechanicalReduction>
        <motorTorqueConstant>1</motorTorqueConstant>
        <pulsesPerRevolution>90000</pulsesPerRevolution>
    </transmission>
    <link name="rfmiddle">
        <inertial>
            <origin rpy="0 0 0" xyz="0 0 0.0125"/>
            <mass value="0.1"/>
            <inertia ixx="0.0000067" ixy="0.0" ixz="0.0" iyy="0.0000067" iyz="0.0" izz="0.0000038"/>
        </inertial>
        <visual>
            <origin rpy="0 0 0" xyz="0 0 0"/>
            <geometry name="middle_visual">
                <mesh filename="sr_description/hand/model/F2.dae" scale="0.001 0.001 0.001"/>
            </geometry>
            <material name="Grey"/>
        </visual>
        <collision>
            <origin rpy="0 0 0" xyz="0 0 0"/>
            <geometry name="middle_collision_geom">
                <mesh filename="sr_description/hand/model/F2.dae" scale="0.001 0.001 0.001"/>
            </geometry>
        </collision>
    </link>
    <joint name="RFJ2" type="revolute">
        <parent link="rfproximal"/>
        <child link="rfmiddle"/>
        <origin rpy="0 0 0" xyz="0 0 0.045"/>
        <axis xyz="1 0 0"/>
        <limit effort="10" lower="0" upper="1.57079632679" velocity="1.0"/>
        <dynamics damping="50.5"/>
    </joint>
    <transmission name="rfmiddle_transmission" type="sr_mechanism_model/J0Transmission">
        <actuator name="RFJ0"/>
        <joint1 name="RFJ1"/>
        <joint2 name="RFJ2"/>
        <mechanicalReduction>1</mechanicalReduction>
        <motorTorqueConstant>1</motorTorqueConstant>
        <pulsesPerRevolution>90000</pulsesPerRevolution>
    </transmission>
    <link name="rfdistal">
        <inertial>
            <mass value="0.1"/>
            <origin xyz="0 0 0.018"/>
            <inertia ixx="0.0000067" ixy="0.0" ixz="0.0" iyy="0.0000067" iyz="0.0" izz="0.0000038"/>
        </inertial>
        <visual>
            <origin rpy="0 0 0" xyz="0 0 0"/>
            <geometry name="distal_visual">
                <mesh filename="sr_description/hand/model/distal_ellipsoid.dae" scale="0.001 0.001 0.001"/>
            </geometry>
            <material name="Grey"/>
        </visual>
        <collision>
            <origin rpy="0 0 0" xyz="0 0 0"/>
            <geometry name="distal_collision_geom">
                <mesh filename="sr_description/hand/model/distal_ellipsoid.dae" scale="0.001 0.001 0.001"/>
            </geometry>
        </collision>
    </link>
    <joint name="RFJ1" type="revolute">
        <parent link="rfmiddle"/>
        <child link="rfdistal"/>
        <origin rpy="0 0 0" xyz="0 0 0.025"/>
        <axis xyz="1 0 0"/>
        <limit effort="10" lower="0" upper="1.57079632679" velocity="1.0"/>
        <dynamics damping="50.5"/>
    </joint>
    <link name="rftip">
        <inertial>
            <mass value="0.001"/>
            <inertia ixx="0.0" ixy="0.0" ixz="0.0" iyy="0.0" iyz="0.0" izz="0.0"/>
        </inertial>
    </link>
    <joint name="RFtip" type="fixed">
        <parent link="rfdistal"/>
        <child link="rftip"/>
        <origin rpy="0 0 0" xyz="0 0 0.026"/>
    </joint>
    <link name="lfmetacarpal">
        <inertial>
            <origin rpy="0 0 0" xyz="0 0 0.04"/>
            <mass value="0.2"/>
            <inertia ixx="0.00003" ixy="0.0" ixz="0.0" iyy="0.00003" iyz="0.0" izz="0.0000075"/>
        </inertial>
        <visual>
            <origin rpy="0 0 0" xyz="0 0 0"/>
            <geometry name="lfmetacarpal_visual">
                <mesh filename="sr_description/hand/model/lfmetacarpal.dae" scale="0.001 0.001 0.001"/>
            </geometry>
            <material name="Grey"/>
        </visual>
        <collision>
            <origin rpy="0 0 0" xyz="0 0 0"/>
            <geometry name="lfmetacarpal_collision_geom">
                <mesh filename="sr_description/hand/model/lfmetacarpal.dae" scale="0.001 0.001 0.001"/>
            </geometry>
        </collision>
    </link>
    <joint name="LFJ5" type="revolute">
        <parent link="palm"/>
        <child link="lfmetacarpal"/>
        <origin rpy="0 0 0" xyz="-0.033 0 0.02071"/>
        <axis xyz="0.573576436 0 0.819152044"/>
        <limit effort="10" lower="0" upper="0.69813170079773179" velocity="1.0"/>
        <dynamics damping="50.5"/>
    </joint>
    <transmission name="lfmetacarpal_transmission" type="sr_mechanism_model/SimpleTransmission">
        <actuator name="LFJ5"/>
        <joint name="LFJ5"/>
        <mechanicalReduction>1</mechanicalReduction>
        <motorTorqueConstant>1</motorTorqueConstant>
        <pulsesPerRevolution>90000</pulsesPerRevolution>
    </transmission>
    <link name="lfknuckle">
        <inertial>
            <origin rpy="0 0 0" xyz="0 0 0"/>
            <mass value="0.008"/>
            <inertia ixx="0.1" ixy="0.0" ixz="0.0" iyy="0.1" iyz="0.0" izz="0.1"/>
        </inertial>
        <visual>
            <origin rpy="0 0 0" xyz="0 0 0"/>
            <geometry name="knuckle_visual">
                <mesh filename="sr_description/hand/model/knuckle.dae" scale="0.001 0.001 0.001"/>
            </geometry>
            <material name="LightGrey"/>
        </visual>
        <collision>
            <origin rpy="0 0 0" xyz="0 0 0"/>
            <geometry name="knuckle_collision_geom">
                <mesh filename="sr_description/hand/model/knuckle.dae" scale="0.001 0.001 0.001"/>
            </geometry>
        </collision>
    </link>
    <joint name="LFJ4" type="revolute">
        <parent link="lfmetacarpal"/>
        <child link="lfknuckle"/>
        <origin rpy="0 0 0" xyz="0 0 0.06579"/>
        <axis xyz="0 1 0"/>
        <limit effort="10" lower="-0.43633231299858238" upper="0.43633231299858238" velocity="1.0"/>
        <dynamics damping="50.5"/>
    </joint>
    <transmission name="lfknuckle_transmission" type="sr_mechanism_model/SimpleTransmission">
        <actuator name="LFJ4"/>
        <joint name="LFJ4"/>
        <mechanicalReduction>1</mechanicalReduction>
        <motorTorqueConstant>1</motorTorqueConstant>
        <pulsesPerRevolution>90000</pulsesPerRevolution>
    </transmission>
    <link name="lfproximal">
        <inertial>
            <mass value="0.2"/>
            <origin xyz="0 0 0.025"/>
            <inertia ixx="0.00003" ixy="0.0" ixz="0.0" iyy="0.00003" iyz="0.0" izz="0.0000075"/>
        </inertial>
        <visual>
            <origin rpy="0 0 0" xyz="0 0 0"/>
            <geometry name="proximal_visual">
                <mesh filename="sr_description/hand/model/F3.dae" scale="0.001 0.001 0.001"/>
            </geometry>
            <material name="Grey"/>
        </visual>
        <collision>
            <origin rpy="0 0 0 " xyz="0 0 0"/>
            <geometry name="proximal_collision_geom">
                <mesh filename="sr_description/hand/model/F3.dae" scale="0.001 0.001 0.001"/>
            </geometry>
        </collision>
    </link>
    <joint name="LFJ3" type="revolute">
        <parent link="lfknuckle"/>
        <child link="lfproximal"/>
        <origin rpy="0 0 0" xyz="0 0 0"/>
        <axis xyz="1 0 0"/>
        <limit effort="10" lower="0" upper="1.57079632679" velocity="1.0"/>
        <dynamics damping="50.5"/>
    </joint>
    <transmission name="lfproximal_transmission" type="sr_mechanism_model/SimpleTransmission">
        <actuator name="LFJ3"/>
        <joint name="LFJ3"/>
        <mechanicalReduction>1</mechanicalReduction>
        <motorTorqueConstant>1</motorTorqueConstant>
        <pulsesPerRevolution>90000</pulsesPerRevolution>
    </transmission>
    <link name="lfmiddle">
        <inertial>
            <origin rpy="0 0 0" xyz="0 0 0.0125"/>
            <mass value="0.1"/>
            <inertia ixx="0.0000067" ixy="0.0" ixz="0.0" iyy="0.0000067" iyz="0.0" izz="0.0000038"/>
        </inertial>
        <visual>
            <origin rpy="0 0 0" xyz="0 0 0"/>
            <geometry name="middle_visual">
                <mesh filename="sr_description/hand/model/F2.dae" scale="0.001 0.001 0.001"/>
            </geometry>
            <material name="Grey"/>
        </visual>
        <collision>
            <origin rpy="0 0 0" xyz="0 0 0"/>
            <geometry name="middle_collision_geom">
                <mesh filename="sr_description/hand/model/F2.dae" scale="0.001 0.001 0.001"/>
            </geometry>
        </collision>
    </link>
    <transmission name="lfmiddle_transmission" type="sr_mechanism_model/J0Transmission">
        <actuator name="LFJ0"/>
        <joint1 name="LFJ1"/>
        <joint2 name="LFJ2"/>
        <mechanicalReduction>1</mechanicalReduction>
        <motorTorqueConstant>1</motorTorqueConstant>
        <pulsesPerRevolution>90000</pulsesPerRevolution>
    </transmission>
    <link name="lfdistal">
        <inertial>
            <mass value="0.1"/>
            <origin xyz="0 0 0.018"/>
            <inertia ixx="0.0000067" ixy="0.0" ixz="0.0" iyy="0.0000067" iyz="0.0" izz="0.0000038"/>
        </inertial>
        <visual>
            <origin rpy="0 0 0" xyz="0 0 0"/>
            <geometry name="distal_visual">
                <mesh filename="sr_description/hand/model/distal_ellipsoid.dae" scale="0.001 0.001 0.001"/>
            </geometry>
            <material name="Grey"/>
        </visual>
        <collision>
            <origin rpy="0 0 0" xyz="0 0 0"/>
            <geometry name="distal_collision_geom">
                <mesh filename="sr_description/hand/model/distal_ellipsoid.dae" scale="0.001 0.001 0.001"/>
            </geometry>
        </collision>
    </link>
    <joint name="LFJ1" type="revolute">
        <parent link="lfmiddle"/>
        <child link="lfdistal"/>
        <origin rpy="0 0 0" xyz="0 0 0.025"/>
        <axis xyz="1 0 0"/>
        <limit effort="10" lower="0" upper="1.57079632679" velocity="1.0"/>
        <dynamics damping="50.5"/>
    </joint>
    <link name="lftip">
        <inertial>
            <mass value="0.001"/>
            <inertia ixx="0.0" ixy="0.0" ixz="0.0" iyy="0.0" iyz="0.0" izz="0.0"/>
        </inertial>
    </link>
    <joint name="LFtip" type="fixed">
        <parent link="lfdistal"/>
        <child link="lftip"/>
        <origin rpy="0 0 0" xyz="0 0 0.026"/>
    </joint>
    <link name="thbase">
        <inertial>
            <mass value="0.010"/>
            <origin rpy="0 0 0" xyz="0 0 0"/>
            <inertia ixx="0.1" ixy="0.0" ixz="0.0" iyy="0.1" iyz="0.0" izz="0.1"/>
        </inertial>
        <visual>
            <origin rpy="0 0 0" xyz="0 0 0"/>
            <geometry name="thbase_visual">
                <box size="0.001 0.001 0.001"/>
            </geometry>
            <material name="shadow_thbase_material">
                <color rgba="0.5 0.5 0.5 1.0"/>
            </material>
        </visual>
        <collision>
            <origin rpy="0 0 0 " xyz="0 0 0"/>
            <geometry name="thbase_collision_geom">
                <box size="0.001 0.001 0.001"/>
            </geometry>
        </collision>
    </link>
    <joint name="THJ5" type="revolute">
        <parent link="palm"/>
        <child link="thbase"/>
        <origin rpy="0 0.785398163397 0" xyz="0.034 -0.0085 0.029"/>
        <axis xyz="0 0 -1.0"/>
        <limit effort="10" lower="-1.047" upper="1.047" velocity="1.0"/>
        <dynamics damping="50.5"/>
    </joint>
    <transmission name="thbase_transmission" type="sr_mechanism_model/SimpleTransmission">
        <actuator name="THJ5"/>
        <joint name="THJ5"/>
        <mechanicalReduction>1</mechanicalReduction>
        <motorTorqueConstant>1</motorTorqueConstant>
        <pulsesPerRevolution>90000</pulsesPerRevolution>
    </transmission>
    <link name="thproximal">
        <inertial>
            <mass value="0.2"/>
            <origin rpy="0 0 0" xyz="0 0 0.019"/>
            <inertia ixx="0.000026" ixy="0.0" ixz="0.0" iyy="0.000026" iyz="0.0" izz="0.000011"/>
        </inertial>
        <visual>
            <origin rpy="0 0 0" xyz="0 0 0"/>
            <geometry name="thproximal_visual">
                <mesh filename="sr_description/hand/model/TH3_z.dae" scale="0.001 0.001 0.001"/>
            </geometry>
            <material name="shadow_thproximal_material">
                <color rgba="0.2 0.2 0.2 1.0"/>
            </material>
        </visual>
        <collision>
            <origin rpy="0 0 0" xyz="0 0 0"/>
            <geometry name="thproximal_collision_geom">
                <mesh filename="sr_description/hand/model/TH3_z.dae" scale="0.001 0.001 0.001"/>
            </geometry>
        </collision>
    </link>
    <joint name="THJ4" type="revolute">
        <parent link="thbase"/>
        <child link="thproximal"/>
        <origin rpy="0 0 0" xyz="0 0 0"/>
        <axis xyz="1.0 0 0"/>
        <limit effort="10" lower="0" upper="1.309" velocity="1.0"/>
        <dynamics damping="50.5"/>
    </joint>
    <transmission name="thproximal_transmission" type="sr_mechanism_model/SimpleTransmission">
        <actuator name="THJ4"/>
        <joint name="THJ4"/>
        <mechanicalReduction>1</mechanicalReduction>
        <motorTorqueConstant>1</motorTorqueConstant>
        <pulsesPerRevolution>90000</pulsesPerRevolution>
    </transmission>
    <link name="thhub">
        <inertial>
            <mass value="0.002"/>
            <origin rpy="0 0 0" xyz="0 0 0"/>
            <inertia ixx="0.1" ixy="0.0" ixz="0.0" iyy="0.1" iyz="0.0" izz="0.1"/>
        </inertial>
        <visual>
            <origin rpy="0 0 0" xyz="0 0 0"/>
            <geometry name="thhub_visual">
                <box size="0.001 0.001 0.001"/>
            </geometry>
            <material name="shadow_thhub_material">
                <color rgba="0.7 0.7 0.7 1.0"/>
            </material>
        </visual>
        <collision>
            <origin rpy="0 0 0 " xyz="0 0 0"/>
            <geometry name="thhub_collision_geom">
                <box size="0.001 0.001 0.001"/>
            </geometry>
        </collision>
    </link>
    <joint name="THJ3" type="revolute">
        <parent link="thproximal"/>
        <child link="thhub"/>
        <origin rpy="0 0 0" xyz="0 0 0.038"/>
        <axis xyz="1 0 0"/>
        <limit effort="10" lower="-0.2618" upper="0.2618" velocity="1.0"/>
        <dynamics damping="50.5"/>
    </joint>
    <transmission name="thhub_transmission" type="sr_mechanism_model/SimpleTransmission">
        <actuator name="THJ3"/>
        <joint name="THJ3"/>
        <mechanicalReduction>1</mechanicalReduction>
        <motorTorqueConstant>1</motorTorqueConstant>
        <pulsesPerRevolution>90000</pulsesPerRevolution>
    </transmission>
    <link name="thmiddle">
        <inertial>
            <mass value="0.1"/>
            <origin rpy="0 0 0" xyz="0 0 0.018"/>
            <inertia ixx="0.00001" ixy="0.0" ixz="0.0" iyy="0.00001" iyz="0.0" izz="0.0000054"/>
        </inertial>
        <visual>
            <origin rpy="0 0 0" xyz="0 0 0"/>
            <geometry name="thmiddle_visual">
                <mesh filename="sr_description/hand/model/TH2_z.dae" scale="0.001 0.001 0.001"/>
            </geometry>
            <material name="shadow_thmiddle_material">
                <color rgba="0.2 0.2 0.2 1.0"/>
            </material>
        </visual>
        <collision>
            <origin rpy="0 0 0 " xyz="0 0 0"/>
            <geometry name="thmiddle_collision_geom">
                <mesh filename="sr_description/hand/model/TH2_z.dae" scale="0.001 0.001 0.001"/>
            </geometry>
        </collision>
    </link>
    <joint name="THJ2" type="revolute">
        <parent link="thhub"/>
        <child link="thmiddle"/>
        <origin rpy="0 0 0" xyz="0 0 0"/>
        <axis xyz="0 -1 0"/>
        <limit effort="10" lower="-0.5237" upper="0.5237" velocity="1.0"/>
        <dynamics damping="50.5"/>
    </joint>
    <transmission name="thmiddle_transmission" type="sr_mechanism_model/SimpleTransmission">
        <actuator name="THJ2"/>
        <joint name="THJ2"/>
        <mechanicalReduction>1</mechanicalReduction>
        <motorTorqueConstant>1</motorTorqueConstant>
        <pulsesPerRevolution>90000</pulsesPerRevolution>
    </transmission>
    <link name="thdistal">
        <inertial>
            <mass value="0.1"/>
            <origin xyz="0 0 0.018"/>
            <inertia ixx="0.0000067" ixy="0.0" ixz="0.0" iyy="0.0000067" iyz="0.0" izz="0.0000038"/>
        </inertial>
        <visual>
            <origin rpy="0 0 0" xyz="0 0.002 0.0025"/>
            <geometry name="thdistal_visual">
                <mesh filename="sr_description/hand/model/distal_ellipsoid.dae" scale="0.001 0.001 0.001"/>
            </geometry>
            <material name="shadow_thmiddle_material">
                <color rgba="0.2 0.2 0.2 1.0"/>
            </material>
        </visual>
        <collision>
            <origin rpy="0 0 0 " xyz="0 0.002 0.0025"/>
            <geometry name="thmiddle_collision_geom">
                <mesh filename="sr_description/hand/model/distal_ellipsoid.dae" scale="0.001 0.001 0.001"/>
            </geometry>
        </collision>
    </link>
    <joint name="THJ1" type="revolute">
        <parent link="thmiddle"/>
        <child link="thdistal"/>
        <origin rpy="0 0 -1.570796327" xyz="0 0 0.032"/>
        <axis xyz="1 0 0"/>
        <limit effort="10" lower="0" upper="1.571" velocity="1.0"/>
        <dynamics damping="50.5"/>
    </joint>
    <link name="thtip">
        <inertial>
            <mass value="0.001"/>
            <inertia ixx="0.0" ixy="0.0" ixz="0.0" iyy="0.0" iyz="0.0" izz="0.0"/>
        </inertial>
    </link>
    <joint name="thtip" type="fixed">
        <parent link="thdistal"/>
        <child link="thtip"/>
        <origin rpy="0 0 0" xyz="0 0 0.0275"/>
    </joint>
    <transmission name="thdistal_transmission" type="sr_mechanism_model/SimpleTransmission">
        <actuator name="THJ1"/>
        <joint name="THJ1"/>
        <mechanicalReduction>1</mechanicalReduction>
        <motorTorqueConstant>1</motorTorqueConstant>
        <pulsesPerRevolution>90000</pulsesPerRevolution>
    </transmission>
</robot>

